Workbook
Name Anthropic: Paramètres!$P$2:$P$8
Name Google: Paramètres!$Q$3:$Q$6
Name MistralAI: Paramètres!$R$2:$R$8
Name Nb_requests: '⚙️Données'!$J$33:$L$33
Name Nb_tokens: '⚙️Données'!$J$36:$K$36
Name Nb_users: '⚙️Données'!$F$33:$H$33
Name OpenAI: Paramètres!$S$2:$S$16
Name Phase_conception: '⚙️Données'!$F$33:$L$33
Name Phase_production: '⚙️Données'!$J$36:$K$36
Name ZoneSaisie: '⚙️Données'!$F$26,'⚙️Données'!#REF!,'⚙️Données'!$J$26,'⚙️Données'!#REF!,'⚙️Données'!$L$26,'⚙️Données'!#REF!,'⚙️Données'!$K$36,'⚙️Données'!$L$33,'⚙️Données'!$H$33

Sheet 📓Notice
C2: Impact'IA
B6: Calculatrice des impacts environnementaux des projets mobilisant des modèles d'IA Générative
B8: Présentation du document
B9: Le développement et l’usage de modèles IA reposent sur des infrastructures techniques pouvant générer des impacts environnementaux significatifs. Cette calculatrice des impacts environnementaux des projets mobilisant des modèles d'IA Générative a été conçue par la Direction RSE et la Direction du Numérique Responsable du groupe SNCF, en collaboration avec Wavestone et Resilio. Objectif de la calculatrice Impact'IA : vous permettre, de manière autonome, d'évaluer trois dimensions environnementales clés associées à l'utilisation d'un modèle d'IA Générative dans votre projet, sur une année : la consommation électrique, le potentiel de réchauffement climatique (i.e. les émissions de gaz à effet de serre) ainsi que l'utilisation d'eau. Périmètre couvert : Impact'IA couvre une bibliothèque de 33 modèles d'IA Générative, correspondant aux principaux modèles des fournisseurs d'IA (Open AI, Anthropic, Mistral AI, Google)
B16: Précisions sur les 3 indicateurs environnementaux modélisés dans cette calculatrice :
B18: Consommation d'électricité | F18: Potentiel de Réchauffement Climatique | J18: Utilisation d'eau
B20: mWh ou Wh ou kWh | F20: mg CO₂e ou g CO₂e ou kg CO₂e | J20: mL ou L ou m³
B23: Guide Utilisateur
B24: Impact'IA est composé de 5 onglets visibles : 📓Notice (vous êtes ici) : Retrouvez la présentation de la calculatrice, ses objectifs, la méthodologie utilisée ainsi que les consignes d'utilisation. ⚙️Données : Renseignez la phase du projet, le modèle d'IA utilisé et les volumes d'usage. 📊Résultats : Visualisez les 3 impacts environnementaux de votre projet (par requête ou par an) ainsi que certaines équivalences. ♻️Bonnes pratiques : Explorez des leviers d'écoconception.
B33: Méthodologie de calcul
B70: Ce tutoriel explique comment ajouter un modèle supplémentaire dans la calculatrice Impact'IA, en respectant la structure du fichier Excel afin de garantir le bon fonctionnement des calculs et des filtres.
B72: Étapes 1. Afficher la feuille des modèles nommée "Modèles_IA" : Clic droit sur un onglet → Afficher… → Modèles_IA 2. Dupliquer une ligne existante : Dans l'onglet Modèles_IA, insérer ou copier / coller une ligne complète sur la ligne vide suivante (obligatoire pour conserver formules et listes déroulantes) 3. Renseigner les champs mentionnées : Nom du modèle, fournisseur, caractéristiques, sources, etc. 4. Vérifier : Dans l'onglet Données, le modèle apparaît dans les listes et les calculs se mettent à jour Bonne pratique : ne pas modifier les formules, colonnes ou cellules verrouillées.
B101: Des questions, difficultés ou suggestions d'améliorations ? | H101: https://github.com/SNCFdevelopers/ImpactIA
B105: Date | F105: Version | I105: Auteurs
B106: 46211 | F106: vF-CC-BY-NC-SA | I106: SNCF : Direction du Numérique Responsable en collaboration avec Wavestone et Resilio.
B107: 46281 | F107: vF-CC-BY-NC-SA | I107: Ajout du choix du mix électrique et de nouveaux modèles. Correction d'erreur dans le calcul du front applicatif. Mise à jour des FE électricité.
B109: Licence : CC-BY-NC-SA

Sheet ⚙️Données
C2: Impact'IA
B6: Calculatrice des impacts environnementaux des projets mobilisant des modèles d'IA Générative
B8: Comment utiliser cette calculatrice ?
B9: 1. Sélectionner la phase de votre projet : Conception ou Production 2. Choisir le fournisseur et le modèle d'IA 2. Renseigner le(s) volume(s) d'usage du projet (Pour les projets en Production, la valeur du nombre de tokens d'entrée et de sortie, ainsi que le nombre de requêtes par mois sont nécessaires. Si vous ne connaissez pas ces valeurs, sélectionnez la phase "Conception" et renseignez les valeurs demandées)
E19: Mon projet est en : | H19: Production
L25: {=IFERROR( FILTRER( Tableau1[Nom du modèle], Tableau1[Fournisseurs] = $F$26 ), "" )}
E26: Fournisseur : | I26: Modèle :
C33: Exemple de taille de requête | D33: Echange court (≈ 400 tokens) | F33: Nombre d'utilisateurs de l'outil: | H33: 1 | J33: Nombre de requêtes (par jour et par utilisateur) | L33: 1
C36: Nombre total de requêtes (par mois) | D36: 100000 | F36: Nombre total de tokens d'entrée (par mois) | H36: 100000000 | J36: Nombre total de tokens de sortie (par mois) | K36: 100000000
F38: Nombre de tokens d'embedding (par mois) | H38: 1000000000
B43: 2
D44: Je ne connais pas le pays d'inférence (valeur France par défaut) | G44: L'inférence a lieu en / au : (menu déroulant) | H44: France | J44: Je renseigne ma propre intensité carbone de l'électricité : | K44: 0 | L44: kgCO2e/kWh
H45: =TEXT(_xlfn.XLOOKUP('⚙️Données'!H44,Tableau2[Sous-catégorie],Tableau2[Valeur],"null"),"0,000")&" kgCO2e/kWh" -> 0,046 kgCO2e/kWh | L45: attention, valeur en kg

Sheet 📊Résultats
C2: Impact'IA
B6: Calculatrice des impacts environnementaux des projets mobilisant des modèles d'IA Générative
I23: Entraînement | L23: {="Inférence"&" : "&_xlfn.SWITCH('⚙️Données'!B43,2,"valeur France par défaut",1,'⚙️Données'!H44,3,"mix personalisé")} -> Inférence : valeur France par défaut
I24: =ROUND(Calcul!M84,2)&" kg CO₂e / kWh" -> 0,46 kg CO₂e / kWh | L24: =ROUND(Calcul!$M$210,2)&" kg CO₂e / kWh" -> 0,05 kg CO₂e / kWh
F41: Résultats > 1000 kgCO2e/an ➜ le projet doit faire l'objet d'une reflexion autour de son impact environnemental Résultats > 10 000 kgCO2e/an ➜ un plan d'action de mitigation des émissions et de mise en oeuvre de bonnes pratiques doit être mis en place.
E149: Les comparaisons de modèles sont réalisées à périmètre fonctionnel constant. Chaque modèle est rattaché à une catégorie de taille et d’usage, considérés comme des alternatives réalistes.
F157: GPT-4.1-mini | J157: Mistral Large | M157: Claude Sonnet 4 | Q157: Gemini 2.5 flash lite

Sheet ♻️Bonnes pratiques
D4: Impact'IA
B8: Calculatrice des impacts environnementaux des projets mobilisant des modèles d'IA Générative

Sheet Calcul
K2: Synthèse de comparaison
K3: Fournisseur | N3: =_xlfn.XLOOKUP(N4,Tableau1[Nom du modèle],Tableau1[Fournisseurs]) -> #N/A | O3: =_xlfn.XLOOKUP(O4,Tableau1[Nom du modèle],Tableau1[Fournisseurs]) -> OpenAI | P3: =_xlfn.XLOOKUP(P4,Tableau1[Nom du modèle],Tableau1[Fournisseurs]) -> Mistral AI | Q3: =_xlfn.XLOOKUP(Q4,Tableau1[Nom du modèle],Tableau1[Fournisseurs]) -> Anthropic | R3: =_xlfn.XLOOKUP(R4,Tableau1[Nom du modèle],Tableau1[Fournisseurs]) -> Google
K4: Modèles | N4: =N24 -> 0 | O4: =O24 -> GPT-4.1-mini | P4: =P24 -> Mistral Large | Q4: =Q24 -> Claude Sonnet 4 | R4: =R24 -> Gemini 2.5 flash lite
K6: =📓Notice!$B$18&" ("&L6&")" -> #DIV/0! | L6: =IF(N33>=1, " kWh / an", IF(N33>=0.001, " Wh / an", " mWh / an" ) ) -> #DIV/0! | N6: =IF($N$33>=1, TEXT(ROUND(N33,0),"# ##0"), IF($N$33>=0.001, TEXT(ROUND(N33*1000,2),"# ##0"), TEXT(ROUND(N33*1000000,0),"# ##0") ) )&" "&$L$6 -> #DIV/0! | O6: =IF($N$33>=1, TEXT(ROUND(O33,0),"# ##0"), IF($N$33>=0.001, TEXT(ROUND(O33*1000,2),"# ##0"), TEXT(ROUND(O33*1000000,0),"# ##0") ) )&" "&$L$6 -> #DIV/0! | P6: =IF($N$33>=1, TEXT(ROUND(P33,0),"# ##0"), IF($N$33>=0.001, TEXT(ROUND(P33*1000,2),"# ##0"), TEXT(ROUND(P33*1000000,0),"# ##0") ) )&" "&$L$6 -> #DIV/0! | Q6: =IF($N$33>=1, TEXT(ROUND(Q33,0),"# ##0"), IF($N$33>=0.001, TEXT(ROUND(Q33*1000,2),"# ##0"), TEXT(ROUND(Q33*1000000,0),"# ##0") ) )&" "&$L$6 -> #DIV/0! | R6: =IF($N$33>=1, TEXT(ROUND(R33,0),"# ##0"), IF($N$33>=0.001, TEXT(ROUND(R33*1000,2),"# ##0"), TEXT(ROUND(R33*1000000,0),"# ##0") ) )&" "&$L$6 -> #DIV/0!
K7: Ecart avec le modèle choisi | N7: =IF( N33/$N$33<1, "👍 x "&TEXT(N33/$N$33,"0,0"), "x "&TEXT(ROUNDUP(N33/$N$33,1),"0,0") ) -> #DIV/0! | O7: =IF( O33/$N$33<1, "👍 x "&TEXT(O33/$N$33,"0,0"), "x "&TEXT(ROUNDUP(O33/$N$33,1),"0,0") ) -> #DIV/0! | P7: =IF( P33/$N$33<1, "👍 x "&TEXT(P33/$N$33,"0,0"), "x "&TEXT(ROUNDUP(P33/$N$33,1),"0,0") ) -> #DIV/0! | Q7: =IF( Q33/$N$33<1, "👍 x "&TEXT(Q33/$N$33,"0,0"), "x "&TEXT(ROUNDUP(Q33/$N$33,1),"0,0") ) -> #DIV/0! | R7: =IF( R33/$N$33<1, "👍 x "&TEXT(R33/$N$33,"0,0"), "x "&TEXT(ROUNDUP(R33/$N$33,1),"0,0") ) -> #DIV/0!
K8: =📓Notice!$B$18&" par requête" -> Consommation d'électricité par requête | L8: =IF(N34>=1, " kWh / requête", IF(N34>=0.001, " Wh / requête", " mWh / requête" ) ) -> mWh / requête | N8: =IF($N$34>=1, ROUND(Calcul!N34,0), IF(Calcul!$N$34>=0.001, ROUND(Calcul!N34*1000,1), ROUND(Calcul!N34*1000000,0) ) )&" "&$L$8 -> 0 mWh / requête | O8: =IF($N$34>=1, ROUND(Calcul!O34,0), IF(Calcul!$N$34>=0.001, ROUND(Calcul!O34*1000,1), ROUND(Calcul!O34*1000000,0) ) )&" "&$L$8 -> 0 mWh / requête | P8: =IF($N$34>=1, ROUND(Calcul!P34,0), IF(Calcul!$N$34>=0.001, ROUND(Calcul!P34*1000,1), ROUND(Calcul!P34*1000000,0) ) )&" "&$L$8 -> 0 mWh / requête | Q8: =IF($N$34>=1, ROUND(Calcul!Q34,0), IF(Calcul!$N$34>=0.001, ROUND(Calcul!Q34*1000,1), ROUND(Calcul!Q34*1000000,0) ) )&" "&$L$8 -> 0 mWh / requête | R8: =IF($N$34>=1, ROUND(Calcul!R34,0), IF(Calcul!$N$34>=0.001, ROUND(Calcul!R34*1000,1), ROUND(Calcul!R34*1000000,0) ) )&" "&$L$8 -> 0 mWh / requête
K9: =📓Notice!$B$18&" par token de sortie" -> Consommation d'électricité par token de sortie | L9: =IF(Calcul!$N$35>=1000, " kWh / token", IF(N35>=0.001, " Wh / token", " mWh / token" ) ) -> mWh / token | N9: =IF(Calcul!$N$35>=1000, ROUND(Calcul!N35/1000,2), IF(Calcul!$N$35>=1, ROUND(Calcul!N35,2), ROUND(Calcul!N35*1000,2) ) )&" "&$L$9 -> 0 mWh / token | O9: =IF(Calcul!$N$35>=1000, ROUND(Calcul!O35/1000,2), IF(Calcul!$N$35>=1, ROUND(Calcul!O35,2), ROUND(Calcul!O35*1000,2) ) )&" "&$L$9 -> 0 mWh / token | P9: =IF(Calcul!$N$35>=1000, ROUND(Calcul!P35/1000,2), IF(Calcul!$N$35>=1, ROUND(Calcul!P35,2), ROUND(Calcul!P35*1000,2) ) )&" "&$L$9 -> 0 mWh / token | Q9: =IF(Calcul!$N$35>=1000, ROUND(Calcul!Q35/1000,2), IF(Calcul!$N$35>=1, ROUND(Calcul!Q35,2), ROUND(Calcul!Q35*1000,2) ) )&" "&$L$9 -> 0 mWh / token | R9: =IF(Calcul!$N$35>=1000, ROUND(Calcul!R35/1000,2), IF(Calcul!$N$35>=1, ROUND(Calcul!R35,2), ROUND(Calcul!R35*1000,2) ) )&" "&$L$9 -> 0 mWh / token
K11: =📓Notice!$F$18&" ("&L11&")" -> #DIV/0! | L11: =IF(N37>=1, " kg CO₂e / an", IF(N37>=0.001, " g CO₂e / an", " mg CO₂e / an" ) ) -> #DIV/0! | N11: =IF($N$37>=1, TEXT(ROUND(N37,0),"# ##0"), IF($N$37>=0.001, TEXT(ROUND(N37*1000,2),"# ##0"), TEXT(ROUND(N37*1000000,0),"# ##0") ) )&" "&$L$11 -> #DIV/0! | O11: =IF($N$37>=1, TEXT(ROUND(O37,0),"# ##0"), IF($N$37>=0.001, TEXT(ROUND(O37*1000,2),"# ##0"), TEXT(ROUND(O37*1000000,0),"# ##0") ) )&" "&$L$11 -> #DIV/0! | P11: =IF($N$37>=1, TEXT(ROUND(P37,0),"# ##0"), IF($N$37>=0.001, TEXT(ROUND(P37*1000,2),"# ##0"), TEXT(ROUND(P37*1000000,0),"# ##0") ) )&" "&$L$11 -> #DIV/0! | Q11: =IF($N$37>=1, TEXT(ROUND(Q37,0),"# ##0"), IF($N$37>=0.001, TEXT(ROUND(Q37*1000,2),"# ##0"), TEXT(ROUND(Q37*1000000,0),"# ##0") ) )&" "&$L$11 -> #DIV/0! | R11: =IF($N$37>=1, TEXT(ROUND(R37,0),"# ##0"), IF($N$37>=0.001, TEXT(ROUND(R37*1000,2),"# ##0"), TEXT(ROUND(R37*1000000,0),"# ##0") ) )&" "&$L$11 -> #DIV/0!
K12: Ecart avec le modèle choisi | N12: =IF( N37/$N$37<1, "👍 x "&TEXT(N37/$N$37,"0,0"), "x "&TEXT(ROUNDUP(N37/$N$37,1),"0,0") ) -> #DIV/0! | O12: =IF( O37/$N$37<1, "👍 x "&TEXT(O37/$N$37,"0,0"), "x "&TEXT(ROUNDUP(O37/$N$37,1),"0,0") ) -> #DIV/0! | P12: =IF( P37/$N$37<1, "👍 x "&TEXT(P37/$N$37,"0,0"), "x "&TEXT(ROUNDUP(P37/$N$37,1),"0,0") ) -> #DIV/0! | Q12: =IF( Q37/$N$37<1, "👍 x "&TEXT(Q37/$N$37,"0,0"), "x "&TEXT(ROUNDUP(Q37/$N$37,1),"0,0") ) -> #DIV/0! | R12: =IF( R37/$N$37<1, "👍 x "&TEXT(R37/$N$37,"0,0"), "x "&TEXT(ROUNDUP(R37/$N$37,1),"0,0") ) -> #DIV/0!
K13: =📓Notice!$F$18&" par requête" -> Potentiel de Réchauffement Climatique par requête | L13: =IF(N38>=1, " kg CO₂e / requête", IF(N38>=0.001, " g CO₂e / requête", " mg CO₂e / requête" ) ) -> mg CO₂e / requête | N13: =IF($N$38>=1, ROUND(N38,0), IF($N$38>=0.001, ROUND(N38*1000,1), ROUND(N38*1000000,0) ) )&" "&$L$13 -> 0 mg CO₂e / requête | O13: =IF($N$38>=1, ROUND(O38,0), IF($N$38>=0.001, ROUND(O38*1000,1), ROUND(O38*1000000,0) ) )&" "&$L$13 -> 0 mg CO₂e / requête | P13: =IF($N$38>=1, ROUND(P38,0), IF($N$38>=0.001, ROUND(P38*1000,1), ROUND(P38*1000000,0) ) )&" "&$L$13 -> 0 mg CO₂e / requête | Q13: =IF($N$38>=1, ROUND(Q38,0), IF($N$38>=0.001, ROUND(Q38*1000,1), ROUND(Q38*1000000,0) ) )&" "&$L$13 -> 0 mg CO₂e / requête | R13: =IF($N$38>=1, ROUND(R38,0), IF($N$38>=0.001, ROUND(R38*1000,1), ROUND(R38*1000000,0) ) )&" "&$L$13 -> 0 mg CO₂e / requête
K14: =📓Notice!$F$18&" par token de sortie" -> Potentiel de Réchauffement Climatique par token de sortie | L14: =IF($N$39>=1000, " kg CO₂e / token", IF($N$39>=0.001, " g CO₂e / token", " mg CO₂e / token" ) ) -> mg CO₂e / token | N14: =IF($N$39>=1000, ROUND(N39/1000,2), IF($N$39>=1, ROUND(N39,2), ROUND(N39*1000,2) ) )&" "&$L$14 -> 0 mg CO₂e / token | O14: =IF($N$39>=1000, ROUND(O39/1000,2), IF($N$39>=1, ROUND(O39,2), ROUND(O39*1000,2) ) )&" "&$L$14 -> 0 mg CO₂e / token | P14: =IF($N$39>=1000, ROUND(P39/1000,2), IF($N$39>=1, ROUND(P39,2), ROUND(P39*1000,2) ) )&" "&$L$14 -> 0 mg CO₂e / token | Q14: =IF($N$39>=1000, ROUND(Q39/1000,2), IF($N$39>=1, ROUND(Q39,2), ROUND(Q39*1000,2) ) )&" "&$L$14 -> 0 mg CO₂e / token | R14: =IF($N$39>=1000, ROUND(R39/1000,2), IF($N$39>=1, ROUND(R39,2), ROUND(R39*1000,2) ) )&" "&$L$14 -> 0 mg CO₂e / token
K16: =📓Notice!$J$18&" ("&L16&")" -> #DIV/0! | L16: =IF(N41>=1000, " m³ eq / an", IF(N41>=1, " L eq / an", " mL eq / an" ) ) -> #DIV/0! | N16: =ROUND(N$41/1000,0)&" "&$L$16 -> #DIV/0! | O16: =ROUND(O$41/1000,0)&" "&$L$16 -> #DIV/0! | P16: =ROUND(P$41/1000,0)&" "&$L$16 -> #DIV/0! | Q16: =ROUND(Q$41/1000,0)&" "&$L$16 -> #DIV/0! | R16: =ROUND(R$41/1000,0)&" "&$L$16 -> #DIV/0!
K17: Ecart avec le modèle choisi | N17: =IF( N41/$N$41<1, "👍 x "&TEXT(N41/$N$41,"0,0"), "x "&TEXT(ROUNDUP(N41/$N$41,1),"0,0") ) -> #DIV/0! | O17: =IF( O41/$N$41<1, "👍 x "&TEXT(O41/$N$41,"0,0"), "x "&TEXT(ROUNDUP(O41/$N$41,1),"0,0") ) -> #DIV/0! | P17: =IF( P41/$N$41<1, "👍 x "&TEXT(P41/$N$41,"0,0"), "x "&TEXT(ROUNDUP(P41/$N$41,1),"0,0") ) -> #DIV/0! | Q17: =IF( Q41/$N$41<1, "👍 x "&TEXT(Q41/$N$41,"0,0"), "x "&TEXT(ROUNDUP(Q41/$N$41,1),"0,0") ) -> #DIV/0! | R17: =IF( R41/$N$41<1, "👍 x "&TEXT(R41/$N$41,"0,0"), "x "&TEXT(ROUNDUP(R41/$N$41,1),"0,0") ) -> #DIV/0!
K18: =📓Notice!$J$18&" par requête" -> Utilisation d'eau par requête | L18: mL eq / requête | N18: =ROUND(N$42*1000,0)&" "&$L$18 -> 0 mL eq / requête | O18: =ROUND(O$42*1000,0)&" "&$L$18 -> 0 mL eq / requête | P18: =ROUND(P$42*1000,0)&" "&$L$18 -> 0 mL eq / requête | Q18: =ROUND(Q$42*1000,0)&" "&$L$18 -> 0 mL eq / requête | R18: =ROUND(R$42*1000,0)&" "&$L$18 -> 0 mL eq / requête
K19: =📓Notice!$J$18&" par token de sortie" -> Utilisation d'eau par token de sortie | L19: mL eq / token | N19: =ROUND(N$43*1000,2)&" "&$L$19 -> 0 mL eq / token | O19: =ROUND(O$43*1000,2)&" "&$L$19 -> 0 mL eq / token | P19: =ROUND(P$43*1000,2)&" "&$L$19 -> 0 mL eq / token | Q19: =ROUND(Q$43*1000,2)&" "&$L$19 -> 0 mL eq / token | R19: =ROUND(R$43*1000,2)&" "&$L$19 -> 0 mL eq / token
J21: Source de la formule | K21: Variable de calcul | L21: Unités | M21: Facteurs
K23: Caractéristique du modèle
C24: Sous étapes du cycle de vie | J24: Données | K24: Modèle sélectionné | L24: - | N24: ='⚙️Données'!$J$26 -> 0 | O24: =📊Résultats!$F$157 -> GPT-4.1-mini | P24: =📊Résultats!$J$157 -> Mistral Large | Q24: =📊Résultats!$M$157 -> Claude Sonnet 4 | R24: =📊Résultats!$Q$157 -> Gemini 2.5 flash lite
C25: ELEC | D25: Elec % | E25: GWP | F25: GES % | G25: WU | H25: EAU % | J25: Modèles_IA | K25: P_total | L25: Milliards de paramètres | N25: =IFERROR(INDEX(Tableau1[], MATCH(N$24, Tableau1[Nom du modèle], 0), MATCH($K$25, Tableau1[#Headers], 0)),0) -> 0 | O25: =IFERROR(INDEX(Tableau1[], MATCH(O$24, Tableau1[Nom du modèle], 0), MATCH($K$25, Tableau1[#Headers], 0)),0) -> 76 | P25: =IFERROR(INDEX(Tableau1[], MATCH(P$24, Tableau1[Nom du modèle], 0), MATCH($K$25, Tableau1[#Headers], 0)),0) -> 122 | Q25: =IFERROR(INDEX(Tableau1[], MATCH(Q$24, Tableau1[Nom du modèle], 0), MATCH($K$25, Tableau1[#Headers], 0)),0) -> 440 | R25: =IFERROR(INDEX(Tableau1[], MATCH(R$24, Tableau1[Nom du modèle], 0), MATCH($K$25, Tableau1[#Headers], 0)),0) -> 18
A26: Total | B26: Total | C26: =N33 -> #DIV/0! | D26: =C26/$C$26 -> #DIV/0! | E26: =N37 -> #DIV/0! | F26: =E26/$E$26 -> #DIV/0! | G26: =N41 -> #DIV/0! | H26: =G26/$G$26 -> #DIV/0! | J26: Modèles_IA | K26: P_active_moyenne | L26: Milliards de paramètres | N26: =IFERROR(INDEX(Tableau1[], MATCH(N$24, Tableau1[Nom du modèle], 0), MATCH($K$26, Tableau1[#Headers], 0)),0) -> 0 | O26: =IFERROR(INDEX(Tableau1[], MATCH(O$24, Tableau1[Nom du modèle], 0), MATCH($K$26, Tableau1[#Headers], 0)),0) -> 76 | P26: =IFERROR(INDEX(Tableau1[], MATCH(P$24, Tableau1[Nom du modèle], 0), MATCH($K$26, Tableau1[#Headers], 0)),0) -> 122 | Q26: =IFERROR(INDEX(Tableau1[], MATCH(Q$24, Tableau1[Nom du modèle], 0), MATCH($K$26, Tableau1[#Headers], 0)),0) -> 88 | R26: =IFERROR(INDEX(Tableau1[], MATCH(R$24, Tableau1[Nom du modèle], 0), MATCH($K$26, Tableau1[#Headers], 0)),0) -> 18
A27: Entrainement | B27: =J62 -> Stockage de la donnée d'entrainement | C27: =N64 -> #DIV/0! | D27: =C27/$C$26 -> #DIV/0! | E27: =N72 -> #DIV/0! | F27: =E27/$E$26 -> #DIV/0! | G27: =N76 -> #DIV/0! | H27: =G27/$G$26 -> #DIV/0! | J27: Données | K27: Nombre de tokens d'entrée générés par le projet | L27: tokens annuels | M27: =IF('⚙️Données'!$H$19="production",'⚙️Données'!$H$36*12,'⚙️Données'!$H$33*'⚙️Données'!$L$33*$M$30*365) -> 1200000000
B28: =J79 -> Expérimentations tests (R&D) | C28: =N81 -> #DIV/0! | D28: =C28/$C$26 -> #DIV/0! | E28: =N83 -> #DIV/0! | F28: =E28/$E$26 -> #DIV/0! | G28: =N86 -> #DIV/0! | H28: =G28/$G$26 -> #DIV/0! | J28: Données | K28: Nombre de tokens de sortie générés par le projet | L28: tokens annuels | M28: =IF('⚙️Données'!$H$19="production",'⚙️Données'!$K$36*12, '⚙️Données'!$H$33*'⚙️Données'!$L$33*IF('⚙️Données'!$D$33="",$M$31,_xlfn.XLOOKUP('⚙️Données'!$D$33,Paramètres!$B$2:$B$4,Paramètres!$C$2:$C$4)*365)) -> 1200000000
B29: =J88 -> Entrainement final du modèle | C29: =N90 -> #DIV/0! | D29: =C29/$C$26 -> #DIV/0! | E29: =N96 -> #DIV/0! | F29: =E29/$E$26 -> #DIV/0! | G29: =N99 -> #DIV/0! | H29: =G29/$G$26 -> #DIV/0! | J29: Modèles_IA | K29: Average TPS | M29: =IFERROR(INDEX(Tableau1[], MATCH(M$24, Tableau1[Nom du modèle], 0), MATCH($K$29, Tableau1[#Headers], 0)),0) -> 0 | N29: =IFERROR(INDEX(Tableau1[], MATCH(N$24, Tableau1[Nom du modèle], 0), MATCH($K$29, Tableau1[#Headers], 0)),0) -> 0 | O29: =IFERROR(INDEX(Tableau1[], MATCH(O$24, Tableau1[Nom du modèle], 0), MATCH($K$29, Tableau1[#Headers], 0)),0) -> 40.2 | P29: =IFERROR(INDEX(Tableau1[], MATCH(P$24, Tableau1[Nom du modèle], 0), MATCH($K$29, Tableau1[#Headers], 0)),0) -> 35.6 | Q29: =IFERROR(INDEX(Tableau1[], MATCH(Q$24, Tableau1[Nom du modèle], 0), MATCH($K$29, Tableau1[#Headers], 0)),0) -> 50 | R29: =IFERROR(INDEX(Tableau1[], MATCH(R$24, Tableau1[Nom du modèle], 0), MATCH($K$29, Tableau1[#Headers], 0)),0) -> 71.5
A30: Inférence | B30: =J122 -> RAG / Embedding (hors Conception) | C30: =N129 -> 0 | D30: =C30/$C$26 -> #DIV/0! | E30: =N136 -> 2.5395557 | F30: =E30/$E$26 -> #DIV/0! | G30: =N140 -> 859.96864 | H30: =G30/$G$26 -> #DIV/0! | J30: Bibliothèque_FE | K30: Moyenne de token d'entrée par requête | L30: tokens d'entrée par requête | M30: =IF('⚙️Données'!$H$19="Production",_xlfn.XLOOKUP($K$30,Tableau2[Variable],Tableau2[Valeur]),_xlfn.XLOOKUP('⚙️Données'!$D$33,Paramètres!$B$2:$B$4,Paramètres!$C$2:$C$4)*5) -> 5000
B31: =J144 -> Front applicatif - pré & post traitements | C31: =N146 -> 192.60426 | D31: =C31/$C$26 -> #DIV/0! | E31: =N151 -> 20.730337 | F31: =E31/$E$26 -> #DIV/0! | G31: =N155 -> 3179.8963 | H31: =G31/$G$26 -> #DIV/0! | J31: Bibliothèque_FE | K31: Moyenne de token de sortie par requête | L31: tokens de sortie par requête | M31: =IF('⚙️Données'!$H$19="Production",_xlfn.XLOOKUP($K$31,Tableau2[Variable],Tableau2[Valeur]),_xlfn.XLOOKUP('⚙️Données'!$D$33,Paramètres!$B$2:$B$4,Paramètres!$C$2:$C$4)) -> 1000
B32: =J161 -> Traitement des requêtes par le modèle | C32: =N163 -> #DIV/0! | D32: =C32/$C$26 -> #DIV/0! | E32: =N205 -> #DIV/0! | F32: =E32/$E$26 -> #DIV/0! | G32: =N235 -> #DIV/0! | H32: =G32/$G$26 -> #DIV/0!
K33: ÉLECTRICITÉ consommée pour le projet | L33: kWh | N33: =N$53+N$104 -> #DIV/0! | O33: =O$53+O$104 -> #DIV/0! | P33: =P$53+P$104 -> #DIV/0! | Q33: =Q$53+Q$104 -> #DIV/0! | R33: =R$53+R$104 -> #DIV/0!
K34: ÉLECTRICITÉ consommée (usage + environnée) pour un requête | L34: kWh | N34: =IFERROR(IF('⚙️Données'!$H$19="production",(N$33/('⚙️Données'!$D$36*12)),N$33/('⚙️Données'!$H$33*'⚙️Données'!$L$33*365)),0) -> 0 | O34: =IFERROR(IF('⚙️Données'!$H$19="production",(O$33/('⚙️Données'!$D$36*12)),O$33/('⚙️Données'!$H$33*'⚙️Données'!$L$33*365)),0) -> 0 | P34: =IFERROR(IF('⚙️Données'!$H$19="production",(P$33/('⚙️Données'!$D$36*12)),P$33/('⚙️Données'!$H$33*'⚙️Données'!$L$33*365)),0) -> 0 | Q34: =IFERROR(IF('⚙️Données'!$H$19="production",(Q$33/('⚙️Données'!$D$36*12)),Q$33/('⚙️Données'!$H$33*'⚙️Données'!$L$33*365)),0) -> 0 | R34: =IFERROR(IF('⚙️Données'!$H$19="production",(R$33/('⚙️Données'!$D$36*12)),R$33/('⚙️Données'!$H$33*'⚙️Données'!$L$33*365)),0) -> 0
B35: Electricité consommée pour le traitement de la requête à l'inférence | E35: Equivalents : | F35: Unité | G35: Eléments de base | H35: Affichage Résultats | K35: ÉLECTRICITÉ consommée (usage + environnée) pour un token | L35: kWh | N35: =IFERROR(N$33/$M$28,0) -> 0 | O35: =IFERROR(O$33/$M$28,0) -> 0 | P35: =IFERROR(P$33/$M$28,0) -> 0 | Q35: =IFERROR(Q$33/$M$28,0) -> 0 | R35: =IFERROR(R$33/$M$28,0) -> 0
B36: GPU | C36: =ROUND(N173,2) -> 48.64 | E36: =ROUNDUP(N33*1000,0) -> #DIV/0! | F36: Wh | G36: 1
B37: Serveur (hors GPU) | C37: =ROUND(N193,2) -> #DIV/0! | E37: =ROUNDUP($E$36*$G$37,0) -> #DIV/0! | F37: recharge(s) de smartphone | G37: 0.1 | H37: =TEXT(E37,"# ##0")&" "&Calcul!F37 -> #DIV/0! | K37: GES émis (usage + embarqué) pour le projet | L37: kg CO₂e | N37: =N$56+N$107 -> #DIV/0! | O37: =O$56+O$107 -> #DIV/0! | P37: =P$56+P$107 -> #DIV/0! | Q37: =Q$56+Q$107 -> #DIV/0! | R37: =R$56+R$107 -> #DIV/0!
B38: Equipements réseaux du centre de données | C38: =ROUND(N197,2) -> #DIV/0! | E38: =ROUNDUP($E$36*$G$38,0) -> #DIV/0! | F38: minute(s) sur Internet | G38: 0.6 | H38: =TEXT(E38,"# ##0")&" "&Calcul!F38 -> #DIV/0! | K38: GES émis (usage + embarqué) pour une requête | L38: kg CO₂e | N38: =IFERROR(IF('⚙️Données'!$H$19="production",(N$37/('⚙️Données'!$D$36*12)),N$37/('⚙️Données'!$H$33*'⚙️Données'!$L$33*365)),0) -> 0 | O38: =IFERROR(IF('⚙️Données'!$H$19="production",(O$37/('⚙️Données'!$D$36*12)),O$37/('⚙️Données'!$H$33*'⚙️Données'!$L$33*365)),0) -> 0 | P38: =IFERROR(IF('⚙️Données'!$H$19="production",(P$37/('⚙️Données'!$D$36*12)),P$37/('⚙️Données'!$H$33*'⚙️Données'!$L$33*365)),0) -> 0 | Q38: =IFERROR(IF('⚙️Données'!$H$19="production",(Q$37/('⚙️Données'!$D$36*12)),Q$37/('⚙️Données'!$H$33*'⚙️Données'!$L$33*365)),0) -> 0 | R38: =IFERROR(IF('⚙️Données'!$H$19="production",(R$37/('⚙️Données'!$D$36*12)),R$37/('⚙️Données'!$H$33*'⚙️Données'!$L$33*365)),0) -> 0
B39: Infrastructures techniques (inc. PUE) | C39: =N163-SUM(C36:C38) -> #DIV/0! | K39: GES émis (usage + embarqué) pour un token | L39: kg CO₂e | N39: =IFERROR(N$37/$M$28,0) -> 0 | O39: =IFERROR(O$37/$M$28,0) -> 0 | P39: =IFERROR(P$37/$M$28,0) -> 0 | Q39: =IFERROR(Q$37/$M$28,0) -> 0 | R39: =IFERROR(R$37/$M$28,0) -> 0
B40: Totale | C40: =SUM(C36:C39) -> #DIV/0! | E40: Equivalents | F40: Unité | G40: Eléments de base | H40: Affichage Résultats
E41: =N37*1000 -> #DIV/0! | F41: gCO2eq | G41: 1 | K41: EAU utilisée pour le projet | L41: L eq | N41: =N$59+N$110 -> #DIV/0! | O41: =O$59+O$110 -> #DIV/0! | P41: =P$59+P$110 -> #DIV/0! | Q41: =Q$59+Q$110 -> #DIV/0! | R41: =R$59+R$110 -> #DIV/0!
E42: =$E$41*G42 -> #DIV/0! | F42: km(s) en voiture | G42: 0.0046 | H42: =TEXT(E42,"# ##0")&" "&F42 -> #DIV/0! | K42: EAU utilisée pour une requête | L42: L eq | N42: =IFERROR(IF('⚙️Données'!$H$19="production",(N$41/('⚙️Données'!$D$36*12)),N$41/('⚙️Données'!$H$33*'⚙️Données'!$L$33*365)),0) -> 0 | O42: =IFERROR(IF('⚙️Données'!$H$19="production",(O$41/('⚙️Données'!$D$36*12)),O$41/('⚙️Données'!$H$33*'⚙️Données'!$L$33*365)),0) -> 0 | P42: =IFERROR(IF('⚙️Données'!$H$19="production",(P$41/('⚙️Données'!$D$36*12)),P$41/('⚙️Données'!$H$33*'⚙️Données'!$L$33*365)),0) -> 0 | Q42: =IFERROR(IF('⚙️Données'!$H$19="production",(Q$41/('⚙️Données'!$D$36*12)),Q$41/('⚙️Données'!$H$33*'⚙️Données'!$L$33*365)),0) -> 0 | R42: =IFERROR(IF('⚙️Données'!$H$19="production",(R$41/('⚙️Données'!$D$36*12)),R$41/('⚙️Données'!$H$33*'⚙️Données'!$L$33*365)),0) -> 0
E43: =$E$41*G43 -> #DIV/0! | F43: heure(s) de visio sur Teams | G43: =17.5/1000 -> 0.0175 | H43: =TEXT(E43,"# ##0")&" "&F43 -> #DIV/0! | K43: EAU utilisée pour un token | L43: L eq | N43: =IFERROR(N$41/$M$28,0) -> 0 | O43: =IFERROR(O$41/$M$28,0) -> 0 | P43: =IFERROR(P$41/$M$28,0) -> 0 | Q43: =IFERROR(Q$41/$M$28,0) -> 0 | R43: =IFERROR(R$41/$M$28,0) -> 0
E45: Equivalents | F45: Unité | G45: Eléments de base | H45: Affichage Résultats
E46: =N41 -> #DIV/0! | F46: L | G46: 1
E47: =$E$46*G47 -> #DIV/0! | F47: bouteille(s) d'eau | G47: 1 | H47: =TEXT(E47,"# ##0")&" "&F47 -> #DIV/0!
...

Sheet Bibliothèque_FE
A1: Catégorie | B1: Sous-catégorie | C1: Variable | D1: Valeur | E1: Unité | F1: Source | G1: MAJ | H1: Commentaire | I1: Valeur historique1 | J1: Source1 | K1: Historique | L1: Source Historique
A2: Bâtiment | B2: Embarqué | C2: Facteur d'émission du batiment et de l'environnement technique | D2: 0.01 | E2: kgCO2eq / kWh | F2: Hubblo (RCP ADEME) | G2: 46111
A3: Eau | B3: Monde | C3: WUE off site - eau utilisée pour produire l'électricité consommée | D3: 3.6737 | E3: L eq | F3: Uptime Inst. 2023 | G3: 46111 | H3: Li et al. (2025)
A4: Eau | B4: CF_Aware | C4: CF_Aware | D4: 1.4 | E4: - | F4: Aware Database | G4: 46111
A5: Electricité | B5: France | C5: Facteur d'émission de l'électricité consommée France | D5: =4.61*10^(-2) -> 0.0461 | E5: kgCO2eq / kWh | F5: Ademe | G5: 46125 | H5: Electricité/2025 - mix moyen/consommation - FR continentale | K5: 0.04418 | L5: Ecologits - ADEME
A6: Electricité | B6: Autre (monde) | C6: Facteur d'émission de l'électricité consommée Monde | D6: 0.458 | E6: kgCO2eq / kWh | F6: Our World in Data | G6: 46113
A7: Embedding | B7: Electricité | C7: Puissance électrique d'un GPU pour l'embedding | D7: 0.7 | E7: kW | F7: Ecologits v0.9 | G7: 46113 | H7: NVIDIA H100 80GB SXM5
A8: Embedding | B8: Configuration | C8: Nombre de GPU utilisé pour l'embedding | D8: 1 | E8: GPU | F8: SNCF | G8: 46113
A9: Entrainement | B9: Embarqué | C9: GES embarqué du stockage HDD de l'entrainement | D9: =1043-402.5 -> 640.5 | E9: kgCO2eq | F9: Resilio DB 03/2026 | G9: 46112 | H9: Seagate Exos 30 TB - a6732f1d11a526d6818449833d73a613672d54918ad5112c0b4b4c077de485b6
A10: Entrainement | B10: Electricité | C10: Puissance électrique du HDD pour le stockage dataset de l'entrainement | D10: =9.5/1000 -> 0.0095 | E10: kW | F10: Kitguru | G10: 46113 | H10: Seagate Exos 30 TB
A11: Entrainement | B11: Durée de vie | C11: Durée d'entrainement | D11: 100 | E11: jours | F11: Epoch.AI | G11: 46113 | H11: Article Epoch.Ai
A12: Entrainement | B12: Ratio | C12: Ratio d'usage HDD | D12: 0.2 | E12: - | F12: Epoch.AI | G12: 46113 | H12: AI models EPOCH AI
A13: Entrainement | B13: Durée de vie | C13: Durée de vie du HDD | D13: 5 | E13: ans | F13: SNCF | G13: 46113
A14: Entrainement | B14: Eau | C14: WU du stockage HDD de l'entrainement (WORLD) | D14: =AVERAGE(270.48-1.07*10^2)*1000 -> 163480 | E14: L eq | F14: Resilio DB 04/2026 | G14: 46136 | H14: Seagate Exos 30 TB - a6732f1d11a526d6818449833d73a613672d54918ad5112c0b4b4c077de485b6
A15: GPU | B15: Configuration | C15: Nombre de GPU par serveur | D15: 8 | E15: GPU | F15: Ecologits v0.9 | G15: 46111
A16: GPU | B16: Durée de vie | C16: Durée de vie d'un GPU | D16: 3 | E16: ans | F16: Ecologits v0.9 | G16: 46111 | J16: Ostrouchov et al. (2020)
A17: GPU | B17: Configuration | C17: Quantification | D17: 16 | E17: Bits | F17: Ecologits v0.9 | G17: 46111
A18: GPU | B18: Configuration | C18: Mémoire GPU | D18: 80 | E18: Go | F18: Ecologits v0.9 | G18: 46111 | H18: NVIDIA H100 80GB HBM3 | J18: Lees-Perasso et al. (2026)
A19: GPU | B19: Energie | C19: GPU_Energy_α | D19: =1.16652731704519*10^(-6) -> 1.1665273e-06 | E19: Wh/tok/Mds | F19: Ecologits v0.9 | G19: 46111
A20: GPU | B20: Energie | C20: GPU_Energy_β | D20: =-0.0112059210255791 -> -0.011205921 | E20: Wh/tok | F20: Ecologits v0.9 | G20: 46111
A21: GPU | B21: Energie | C21: GPU_Energy_γ | D21: =4.052928146734*10^(-5) -> 4.0529281e-05 | E21: Wh | F21: Ecologits v0.9 | G21: 46111
A22: GPU | B22: Configuration | C22: Batch | D22: 64 | E22: nombre de requête | F22: Ecologits v0.9 | G22: 46111
A23: GPU | B23: Latence | C23: Latence_α | D23: 0.00067850881 | E23: s/tok/Mds | F23: Ecologits v0.9 | G23: 46111
A24: GPU | B24: Latence | C24: Latence_β | D24: 0.00031193103 | E24: s/tok | F24: Ecologits v0.9 | G24: 46111
A25: GPU | B25: Latence | C25: Latence_γ | D25: 0.019473718 | E25: s | F25: Ecologits v0.9 | G25: 46111
A26: GPU | B26: Embarqué | C26: GES embarqué d'un seul GPU | D26: 366.54 | E26: kgCO2eq | F26: Resilio DB 03/2026 | G26: 46111 | H26: NVIDIA H100 80GB SXM5 - c5c38823a29224c78a48b7fd33c77b47fcfb74a4655ae68a0de9002f1fa301be | I26: 273 | J26: Ecologits v0.10 - NVIDIA H100 80GB HBM3 - Lees-Perasso et al. (2026) | K26: 164 | L26: Falk et al. 2025
A27: GPU | B27: Eau | C27: WU d'un seul GPU (embarqué) | D27: =101.5*1000 -> 101500 | E27: L eq | F27: Resilio DB 04/2026 | G27: 46136 | H27: NVIDIA H100 80GB SXM5 - c5c38823a29224c78a48b7fd33c77b47fcfb74a4655ae68a0de9002f1fa301be
A28: Inférence | B28: Ratio | C28: Ratio d'inférence sur la compute capacity | D28: 0.8 | F28: SNCF | G28: 46136
A29: Réseau | B29: Electricité | C29: Puissance électrique des pares-feux | D29: 0.09 | E29: kW | F29: Ademe | G29: 46111
A30: Réseau | B30: Ratio | C30: Ratio d'usage pares-feux | D30: 0.0358 | E30: - | F30: ADEME - ARCEP | G30: 46111
A31: Réseau | B31: Electricité | C31: Puissance électrique des routeurs | D31: 0.09 | E31: kW | F31: Ademe | G31: 46111
A32: Réseau | B32: Ratio | C32: Ratio d'usage routeurs | D32: 0.286 | E32: - | F32: ADEME - ARCEP | G32: 46111
A33: Réseau | B33: Electricité | C33: Puissance électrique des switches | D33: 0.09 | E33: kW | F33: Ademe | G33: 46111
A34: Réseau | B34: Ratio | C34: Ratio d'usage switches | D34: 1.468 | F34: ADEME - ARCEP | G34: 46111
A35: Réseau | B35: Durée de vie | C35: Durée de vie équipements réseau | D35: 5 | E35: ans | F35: Ademe | G35: 46111
A36: Réseau | B36: Embarqué | C36: GES embarqué du pare-feu | D36: =1073-739.2 -> 333.8 | E36: kgCO2eq | F36: Resilio DB 03/2026 | G36: 46111 | H36: Fortinet FortiGate 100E Firewall - 2bc89e4b2064dba552275a82c26df6c6400edb6442592ebd8d86cbb42cb9af90 | K36: 391 | L36: Hubblo (RCP Ademe)
A37: Réseau | B37: Eau | C37: WU du pare-feu (FR) | D37: =(1315.55-1.22*10^3)*1000 -> 95550 | E37: L eq | F37: Resilio DB 03/2026 | G37: 46111 | H37: Fortinet FortiGate 100E Firewall - 2bc89e4b2064dba552275a82c26df6c6400edb6442592ebd8d86cbb42cb9af90
A38: Réseau | B38: Embarqué | C38: GES embarqué du routeur | D38: =2439-2036 -> 403 | E38: kgCO2eq | F38: Resilio DB 03/2026 | G38: 46111 | H38: Juniper PTX10002‑36QDD - ae4208b57522c4e79278b460a4c1e4875bdb1edd594698d575c7722ee96e4ffb | K38: 391 | L38: Hubblo (RCP Ademe)
A39: Réseau | B39: Eau | C39: WU du routeur (FR) | D39: =(3484.72-3.37*10^3)*1000 -> 114720 | E39: L eq | F39: Resilio DB 03/2026 | G39: 46111 | H39: Juniper PTX10002‑36QDD - ae4208b57522c4e79278b460a4c1e4875bdb1edd594698d575c7722ee96e4ffb
A40: Réseau | B40: Embarqué | C40: GES embarqué du switch | D40: =1633-1270 -> 363 | E40: kgCO2eq | F40: Resilio DB 03/2026 | G40: 46111 | H40: Arista 7050TX3-48C8 - bd728dcdba0474ed95ff155182665f5bec3fda22a25a9bb0da8c560a63fb33ae | K40: 391 | L40: Hubblo (RCP Ademe)
...

Sheet Modèles_IA
A1: SNCF | B1: Fournisseurs | C1: Nom du modèle | D1: Catégorie | E1: Architecture | F1: P_total (Mds) | G1: P_total_min | H1: P_total_max | I1: P_active_min (Mds) | J1: P_active_max (Mds) | K1: Sources | L1: Localisation | M1: PUE | N1: Source PUE | O1: WUE on-site - eau utilisée directement dans le centre de donnée | P1: Source WUE | Q1: P_total | R1: P_active_moyenne | S1: Average TPS | T1: Average TTFT | U1: Coefficient | V1: Estimation du nombre de requêtes par jour (par fournisseurs) | W1: Source | X1: Energie consommée pour un FLOP | Y1: Nombre de tokens à l'entrainement | Z1: Date de publication | AA1: Source2 | AB1: Active_model | AC1: Compute Capacity (kW) | AD1: Source Compute
A2: Oui | B2: Anthropic | C2: Claude Haiku 3 | D2: Moyen | E2: MoE | F2: 300 | I2: 30 | J2: 90 | K2: ['https://docs.anthropic.com/en/docs/about-claude/models'] | L2: USA | M2: =AVERAGE(1.09,1.14) -> 1.115 | N2: "- 1.09 for Google in 2024, average of US data centers (https://www.gstatic.com/gumdrop/sustainability/google-2025-environmental-report.pdf) - 1.14 for AWS in 2024 (https://sustainability.aboutamazon.com/products-services/aws-cloud)" | O2: =AVERAGE(0.13,0.99) -> 0.56 | P2: "- 0.13 for AWS in 2024 (https://sustainability.aboutamazon.com/products-services/aws-cloud) - 0.999 for Google in 2024 (https://www.gstatic.com/gumdrop/sustainability/google-2025-environmental-report.pdf)" | Q2: =IF( NOT(ISBLANK(F2)), F2, IF( AND(NOT(ISBLANK(G2)), NOT(ISBLANK(H2))), INT(AVERAGE(G2, H2)), "" ) ) -> 300 | R2: =IF( NOT(ISBLANK(I2)), INT(AVERAGE(I2,J2)), IF( AND(NOT(ISBLANK(G2)), NOT(ISBLANK(H2))), INT(AVERAGE(G2, H2)), "" ) ) -> 60 | S2: 74.2 | T2: 0.53 | U2: =0.062*(Tableau1[[#This Row],[Average TTFT]]/0.44) -> 0.074681818 | V2: =1000000000 -> 1000000000 | W2: https://www.demandsage.com/claude-ai-statistics/ | X2: =2.25*(10^12) -> 2250000000000 | Y2: =1500*(1-EXP(-(Tableau1[[#This Row],[P_total]]^2)/1000))*Tableau1[[#This Row],[P_total]]*10^9 -> 450000000000000 | Z2: 45358 | AA2: Claude | AB2: =IF(Tableau1[[#This Row],[Date de publication]]>=EDATE(TODAY(),-24),"Oui","Non") -> Non | AC2: 1400000 | AD2: https://wccftech.com/openai-sets-goal-to-scale-up-ai-compute-capacity-to-a-whopping-30gw-by-2030/
A3: Oui | B3: Anthropic | C3: Claude Haiku 4.5 | D3: Moyen | E3: Dense | G3: 10 | H3: 35 | K3: ['https://docs.anthropic.com/en/docs/about-claude/models'] | L3: USA | M3: =AVERAGE(1.09,1.14) -> 1.115 | N3: "- 1.09 for Google in 2024, average of US data centers (https://www.gstatic.com/gumdrop/sustainability/google-2025-environmental-report.pdf) - 1.14 for AWS in 2024 (https://sustainability.aboutamazon.com/products-services/aws-cloud)" | O3: =AVERAGE(0.13,0.99) -> 0.56 | P3: "- 0.13 for AWS in 2024 (https://sustainability.aboutamazon.com/products-services/aws-cloud) - 0.999 for Google in 2024 (https://www.gstatic.com/gumdrop/sustainability/google-2025-environmental-report.pdf)" | Q3: =IF( NOT(ISBLANK(F3)), F3, IF( AND(NOT(ISBLANK(G3)), NOT(ISBLANK(H3))), INT(AVERAGE(G3, H3)), "" ) ) -> 22 | R3: =IF( NOT(ISBLANK(I3)), INT(AVERAGE(I3,J3)), IF( AND(NOT(ISBLANK(G3)), NOT(ISBLANK(H3))), INT(AVERAGE(G3, H3)), "" ) ) -> 22 | S3: 70 | T3: 0.67 | U3: =0.062*(Tableau1[[#This Row],[Average TTFT]]/0.44) -> 0.094409091 | V3: 1000000000 | W3: https://www.demandsage.com/claude-ai-statistics/ | X3: =2.25*(10^12) -> 2250000000000 | Y3: =1500*(1-EXP(-(Tableau1[[#This Row],[P_total]]^2)/1000))*Tableau1[[#This Row],[P_total]]*10^9 -> 1.2661664e+13 | Z3: 45945 | AA3: Epoch Ai | AB3: =IF(Tableau1[[#This Row],[Date de publication]]>=EDATE(TODAY(),-24),"Oui","Non") -> Oui | AC3: 1400000 | AD3: https://wccftech.com/openai-sets-goal-to-scale-up-ai-compute-capacity-to-a-whopping-30gw-by-2030/
A4: Oui | B4: Anthropic | C4: Claude Sonnet 3.7 | D4: Moyen | E4: MoE | F4: 440 | I4: 44 | J4: 132 | K4: ['https://docs.anthropic.com/en/docs/about-claude/models'] | L4: USA | M4: =AVERAGE(1.09,1.14) -> 1.115 | N4: "- 1.09 for Google in 2024, average of US data centers (https://www.gstatic.com/gumdrop/sustainability/google-2025-environmental-report.pdf) - 1.14 for AWS in 2024 (https://sustainability.aboutamazon.com/products-services/aws-cloud)" | O4: =AVERAGE(0.13,0.99) -> 0.56 | P4: "- 0.13 for AWS in 2024 (https://sustainability.aboutamazon.com/products-services/aws-cloud) - 0.999 for Google in 2024 (https://www.gstatic.com/gumdrop/sustainability/google-2025-environmental-report.pdf)" | Q4: =IF( NOT(ISBLANK(F4)), F4, IF( AND(NOT(ISBLANK(G4)), NOT(ISBLANK(H4))), INT(AVERAGE(G4, H4)), "" ) ) -> 440 | R4: =IF( NOT(ISBLANK(I4)), INT(AVERAGE(I4,J4)), IF( AND(NOT(ISBLANK(G4)), NOT(ISBLANK(H4))), INT(AVERAGE(G4, H4)), "" ) ) -> 88 | S4: 46 | T4: 1.31 | U4: =0.062*(Tableau1[[#This Row],[Average TTFT]]/0.44) -> 0.18459091 | V4: 1000000000 | W4: https://www.demandsage.com/claude-ai-statistics/ | X4: =2.25*(10^12) -> 2250000000000 | Y4: =1500*(1-EXP(-(Tableau1[[#This Row],[P_total]]^2)/1000))*Tableau1[[#This Row],[P_total]]*10^9 -> 660000000000000 | Z4: 45712 | AA4: Epoch Ai | AB4: =IF(Tableau1[[#This Row],[Date de publication]]>=EDATE(TODAY(),-24),"Oui","Non") -> Oui | AC4: 1400000 | AD4: https://wccftech.com/openai-sets-goal-to-scale-up-ai-compute-capacity-to-a-whopping-30gw-by-2030/
A5: Oui | B5: Anthropic | C5: Claude Sonnet 4 | D5: Grand | E5: MoE | F5: 440 | I5: 44 | J5: 132 | K5: ['https://docs.anthropic.com/en/docs/about-claude/models'] | L5: USA | M5: =AVERAGE(1.09,1.14) -> 1.115 | N5: "- 1.09 for Google in 2024, average of US data centers (https://www.gstatic.com/gumdrop/sustainability/google-2025-environmental-report.pdf) - 1.14 for AWS in 2024 (https://sustainability.aboutamazon.com/products-services/aws-cloud)" | O5: =AVERAGE(0.13,0.99) -> 0.56 | P5: "- 0.13 for AWS in 2024 (https://sustainability.aboutamazon.com/products-services/aws-cloud) - 0.999 for Google in 2024 (https://www.gstatic.com/gumdrop/sustainability/google-2025-environmental-report.pdf)" | Q5: =IF( NOT(ISBLANK(F5)), F5, IF( AND(NOT(ISBLANK(G5)), NOT(ISBLANK(H5))), INT(AVERAGE(G5, H5)), "" ) ) -> 440 | R5: =IF( NOT(ISBLANK(I5)), INT(AVERAGE(I5,J5)), IF( AND(NOT(ISBLANK(G5)), NOT(ISBLANK(H5))), INT(AVERAGE(G5, H5)), "" ) ) -> 88 | S5: 50 | T5: 1.31 | U5: =0.062*(Tableau1[[#This Row],[Average TTFT]]/0.44) -> 0.18459091 | V5: 1000000000 | W5: https://www.demandsage.com/claude-ai-statistics/ | X5: =2.25*(10^12) -> 2250000000000 | Y5: =1500*(1-EXP(-(Tableau1[[#This Row],[P_total]]^2)/1000))*Tableau1[[#This Row],[P_total]]*10^9 -> 660000000000000 | Z5: 45799 | AA5: Epoch Ai | AB5: =IF(Tableau1[[#This Row],[Date de publication]]>=EDATE(TODAY(),-24),"Oui","Non") -> Oui | AC5: 1400000 | AD5: https://wccftech.com/openai-sets-goal-to-scale-up-ai-compute-capacity-to-a-whopping-30gw-by-2030/
A6: Oui | B6: Anthropic | C6: Claude Sonnet 4.5 | D6: Grand | E6: MoE | F6: 440 | I6: 44 | J6: 132 | K6: ['https://docs.anthropic.com/en/docs/about-claude/models'] | L6: USA | M6: =AVERAGE(1.09,1.14) -> 1.115 | N6: "- 1.09 for Google in 2024, average of US data centers (https://www.gstatic.com/gumdrop/sustainability/google-2025-environmental-report.pdf) - 1.14 for AWS in 2024 (https://sustainability.aboutamazon.com/products-services/aws-cloud)" | O6: =AVERAGE(0.13,0.99) -> 0.56 | P6: "- 0.13 for AWS in 2024 (https://sustainability.aboutamazon.com/products-services/aws-cloud) - 0.999 for Google in 2024 (https://www.gstatic.com/gumdrop/sustainability/google-2025-environmental-report.pdf)" | Q6: =IF( NOT(ISBLANK(F6)), F6, IF( AND(NOT(ISBLANK(G6)), NOT(ISBLANK(H6))), INT(AVERAGE(G6, H6)), "" ) ) -> 440 | R6: =IF( NOT(ISBLANK(I6)), INT(AVERAGE(I6,J6)), IF( AND(NOT(ISBLANK(G6)), NOT(ISBLANK(H6))), INT(AVERAGE(G6, H6)), "" ) ) -> 88 | S6: 36 | T6: 1.63 | U6: =0.062*(Tableau1[[#This Row],[Average TTFT]]/0.44) -> 0.22968182 | V6: 1000000000 | W6: https://www.demandsage.com/claude-ai-statistics/ | X6: =2.25*(10^12) -> 2250000000000 | Y6: =1500*(1-EXP(-(Tableau1[[#This Row],[P_total]]^2)/1000))*Tableau1[[#This Row],[P_total]]*10^9 -> 660000000000000 | Z6: 45929 | AA6: Epoch Ai | AB6: =IF(Tableau1[[#This Row],[Date de publication]]>=EDATE(TODAY(),-24),"Oui","Non") -> Oui | AC6: 1400000 | AD6: https://wccftech.com/openai-sets-goal-to-scale-up-ai-compute-capacity-to-a-whopping-30gw-by-2030/
A7: Non | B7: Anthropic | C7: Claude Sonnet 4.6 | D7: Grand | E7: MoE | F7: 440 | I7: 44 | J7: 132 | K7: ['https://docs.anthropic.com/en/docs/about-claude/models'] | L7: USA | M7: =AVERAGE(1.09,1.14) -> 1.115 | N7: "- 1.09 for Google in 2024, average of US data centers (https://www.gstatic.com/gumdrop/sustainability/google-2025-environmental-report.pdf) - 1.14 for AWS in 2024 (https://sustainability.aboutamazon.com/products-services/aws-cloud)" | O7: =AVERAGE(0.13,0.99) -> 0.56 | P7: "- 0.13 for AWS in 2024 (https://sustainability.aboutamazon.com/products-services/aws-cloud) - 0.999 for Google in 2024 (https://www.gstatic.com/gumdrop/sustainability/google-2025-environmental-report.pdf)" | Q7: =IF( NOT(ISBLANK(F7)), F7, IF( AND(NOT(ISBLANK(G7)), NOT(ISBLANK(H7))), INT(AVERAGE(G7, H7)), "" ) ) -> 440 | R7: =IF( NOT(ISBLANK(I7)), INT(AVERAGE(I7,J7)), IF( AND(NOT(ISBLANK(G7)), NOT(ISBLANK(H7))), INT(AVERAGE(G7, H7)), "" ) ) -> 88 | S7: 41 | T7: 1.68 | U7: =0.062*(Tableau1[[#This Row],[Average TTFT]]/0.44) -> 0.23672727 | V7: 1000000000 | W7: https://www.demandsage.com/claude-ai-statistics/ | X7: =2.25*(10^12) -> 2250000000000 | Y7: =1500*(1-EXP(-(Tableau1[[#This Row],[P_total]]^2)/1000))*Tableau1[[#This Row],[P_total]]*10^9 -> 660000000000000 | Z7: 46070 | AA7: Claude | AB7: =IF(Tableau1[[#This Row],[Date de publication]]>=EDATE(TODAY(),-24),"Oui","Non") -> Oui | AC7: 1400000 | AD7: https://wccftech.com/openai-sets-goal-to-scale-up-ai-compute-capacity-to-a-whopping-30gw-by-2030/
A8: Non | B8: Anthropic | C8: Claude Opus 4.6 | D8: Grand | E8: MoE | F8: 670 | I8: 67 | J8: 200 | K8: ['https://docs.anthropic.com/en/docs/about-claude/models'] | L8: USA | M8: =AVERAGE(1.09,1.14) -> 1.115 | N8: "- 1.09 for Google in 2024, average of US data centers (https://www.gstatic.com/gumdrop/sustainability/google-2025-environmental-report.pdf) - 1.14 for AWS in 2024 (https://sustainability.aboutamazon.com/products-services/aws-cloud)" | O8: =AVERAGE(0.13,0.99) -> 0.56 | P8: "- 0.13 for AWS in 2024 (https://sustainability.aboutamazon.com/products-services/aws-cloud) - 0.999 for Google in 2024 (https://www.gstatic.com/gumdrop/sustainability/google-2025-environmental-report.pdf)" | Q8: =IF( NOT(ISBLANK(F8)), F8, IF( AND(NOT(ISBLANK(G8)), NOT(ISBLANK(H8))), INT(AVERAGE(G8, H8)), "" ) ) -> 670 | R8: =IF( NOT(ISBLANK(I8)), INT(AVERAGE(I8,J8)), IF( AND(NOT(ISBLANK(G8)), NOT(ISBLANK(H8))), INT(AVERAGE(G8, H8)), "" ) ) -> 133 | S8: 33.2 | T8: 2.45 | U8: =0.062*(Tableau1[[#This Row],[Average TTFT]]/0.44) -> 0.34522727 | V8: 1000000000 | W8: https://www.demandsage.com/claude-ai-statistics/ | X8: =2.25*(10^12) -> 2250000000000 | Y8: =1500*(1-EXP(-(Tableau1[[#This Row],[P_total]]^2)/1000))*Tableau1[[#This Row],[P_total]]*10^9 -> 1.005e+15 | Z8: 46058 | AA8: AI sister | AB8: =IF(Tableau1[[#This Row],[Date de publication]]>=EDATE(TODAY(),-24),"Oui","Non") -> Oui | AC8: 1400000 | AD8: https://wccftech.com/openai-sets-goal-to-scale-up-ai-compute-capacity-to-a-whopping-30gw-by-2030/
A9: Oui | B9: Google | C9: Gemini 2.5 flash | D9: Moyen | E9: MoE | F9: 440 | I9: 44 | J9: 132 | K9: ['https://ai.google.dev/gemini-api/docs/models'] | L9: USA | M9: 1.09 | N9: "Average for US data centers in 2024 (1.06, 1.11, 1.07, 1.10, 1.06, 1.09, 1.09, 1.10, 1.13, 1.09, 1.08, 1.11, 1.10, 1.10, 1.07, 1.09, 1.16) https://www.gstatic.com/gumdrop/sustainability/google-2025-environmental-report.pdf (page 109)" | O9: 0.99 | P9: "Total data center electricity consumption and water consumption in 2024 are respectively 30,825,600 MWh and 8,135 Million gallons. https://www.gstatic.com/gumdrop/sustainability/google-2025-environmental-report.pdf" | Q9: =IF( NOT(ISBLANK(F9)), F9, IF( AND(NOT(ISBLANK(G9)), NOT(ISBLANK(H9))), INT(AVERAGE(G9, H9)), "" ) ) -> 440 | R9: =IF( NOT(ISBLANK(I9)), INT(AVERAGE(I9,J9)), IF( AND(NOT(ISBLANK(G9)), NOT(ISBLANK(H9))), INT(AVERAGE(G9, H9)), "" ) ) -> 88 | S9: 66.9 | T9: 0.74 | U9: =0.062*(Tableau1[[#This Row],[Average TTFT]]/0.44) -> 0.10427273 | V9: 3000000000 | W9: https://www.technobezz.com/news/google-slashes-free-gemini-api-requests-to-20-per-day-2025-12-20-gl06 | X9: =2.25*(10^12) -> 2250000000000 | Y9: =1500*(1-EXP(-(Tableau1[[#This Row],[P_total]]^2)/1000))*Tableau1[[#This Row],[P_total]]*10^9 -> 660000000000000 | Z9: 45825 | AA9: Google | AB9: =IF(Tableau1[[#This Row],[Date de publication]]>=EDATE(TODAY(),-24),"Oui","Non") -> Oui | AC9: 9000000 | AD9: https://www.cnbc.com/2025/11/21/google-must-double-ai-serving-capacity-every-6-months-to-meet-demand.html
A10: Oui | B10: Google | C10: Gemini 2.5 flash image | D10: Hors catégorie | E10: MoE | F10: 440 | I10: 44 | J10: 132 | K10: ['https://ai.google.dev/gemini-api/docs/models'] | L10: USA | M10: 1.09 | N10: "Average for US data centers in 2024 (1.06, 1.11, 1.07, 1.10, 1.06, 1.09, 1.09, 1.10, 1.13, 1.09, 1.08, 1.11, 1.10, 1.10, 1.07, 1.09, 1.16) https://www.gstatic.com/gumdrop/sustainability/google-2025-environmental-report.pdf (page 109)" | O10: 0.99 | P10: "Total data center electricity consumption and water consumption in 2024 are respectively 30,825,600 MWh and 8,135 Million gallons. https://www.gstatic.com/gumdrop/sustainability/google-2025-environmental-report.pdf" | Q10: =IF( NOT(ISBLANK(F10)), F10, IF( AND(NOT(ISBLANK(G10)), NOT(ISBLANK(H10))), INT(AVERAGE(G10, H10)), "" ) ) -> 440 | R10: =IF( NOT(ISBLANK(I10)), INT(AVERAGE(I10,J10)), IF( AND(NOT(ISBLANK(G10)), NOT(ISBLANK(H10))), INT(AVERAGE(G10, H10)), "" ) ) -> 88 | S10: 110.8 | T10: 5.87 | U10: =0.062*(Tableau1[[#This Row],[Average TTFT]]/0.44) -> 0.82713636 | V10: 3000000000 | W10: https://www.technobezz.com/news/google-slashes-free-gemini-api-requests-to-20-per-day-2025-12-20-gl06 | X10: =2.25*(10^12) -> 2250000000000 | Y10: =1500*(1-EXP(-(Tableau1[[#This Row],[P_total]]^2)/1000))*Tableau1[[#This Row],[P_total]]*10^9 -> 660000000000000 | Z10: 45932 | AA10: Google | AB10: =IF(Tableau1[[#This Row],[Date de publication]]>=EDATE(TODAY(),-24),"Oui","Non") -> Oui | AC10: 9000000 | AD10: https://www.cnbc.com/2025/11/21/google-must-double-ai-serving-capacity-every-6-months-to-meet-demand.html
A11: Non | B11: Google | C11: Gemini 2.5 flash lite | D11: Petit | E11: Dense | G11: 8 | H11: 28 | K11: ['https://ai.google.dev/gemini-api/docs/models'] | L11: USA | M11: 1.09 | N11: "Average for US data centers in 2024 (1.06, 1.11, 1.07, 1.10, 1.06, 1.09, 1.09, 1.10, 1.13, 1.09, 1.08, 1.11, 1.10, 1.10, 1.07, 1.09, 1.16) https://www.gstatic.com/gumdrop/sustainability/google-2025-environmental-report.pdf (page 109)" | O11: 0.99 | P11: "Total data center electricity consumption and water consumption in 2024 are respectively 30,825,600 MWh and 8,135 Million gallons. https://www.gstatic.com/gumdrop/sustainability/google-2025-environmental-report.pdf" | Q11: =IF( NOT(ISBLANK(F11)), F11, IF( AND(NOT(ISBLANK(G11)), NOT(ISBLANK(H11))), INT(AVERAGE(G11, H11)), "" ) ) -> 18 | R11: =IF( NOT(ISBLANK(I11)), INT(AVERAGE(I11,J11)), IF( AND(NOT(ISBLANK(G11)), NOT(ISBLANK(H11))), INT(AVERAGE(G11, H11)), "" ) ) -> 18 | S11: 71.5 | T11: 0.56 | U11: =0.062*(Tableau1[[#This Row],[Average TTFT]]/0.44) -> 0.078909091 | V11: 3000000000 | W11: https://www.technobezz.com/news/google-slashes-free-gemini-api-requests-to-20-per-day-2025-12-20-gl06 | X11: =2.25*(10^12) -> 2250000000000 | Y11: =1500*(1-EXP(-(Tableau1[[#This Row],[P_total]]^2)/1000))*Tableau1[[#This Row],[P_total]]*10^9 -> 7.4722435e+12 | Z11: 45860 | AA11: Google | AB11: =IF(Tableau1[[#This Row],[Date de publication]]>=EDATE(TODAY(),-24),"Oui","Non") -> Oui | AC11: 9000000 | AD11: https://www.cnbc.com/2025/11/21/google-must-double-ai-serving-capacity-every-6-months-to-meet-demand.html
A12: Oui | B12: Google | C12: Gemini 2.5 pro | D12: Grand | E12: MoE | F12: 2000 | I12: 200 | J12: 600 | K12: ['https://ai.google.dev/gemini-api/docs/models'] | L12: USA | M12: 1.09 | N12: "Average for US data centers in 2024 (1.06, 1.11, 1.07, 1.10, 1.06, 1.09, 1.09, 1.10, 1.13, 1.09, 1.08, 1.11, 1.10, 1.10, 1.07, 1.09, 1.16) https://www.gstatic.com/gumdrop/sustainability/google-2025-environmental-report.pdf (page 109)" | O12: 0.99 | P12: "Total data center electricity consumption and water consumption in 2024 are respectively 30,825,600 MWh and 8,135 Million gallons. https://www.gstatic.com/gumdrop/sustainability/google-2025-environmental-report.pdf" | Q12: =IF( NOT(ISBLANK(F12)), F12, IF( AND(NOT(ISBLANK(G12)), NOT(ISBLANK(H12))), INT(AVERAGE(G12, H12)), "" ) ) -> 2000 | R12: =IF( NOT(ISBLANK(I12)), INT(AVERAGE(I12,J12)), IF( AND(NOT(ISBLANK(G12)), NOT(ISBLANK(H12))), INT(AVERAGE(G12, H12)), "" ) ) -> 400 | S12: 91.1 | T12: 2.83 | U12: =0.062*(Tableau1[[#This Row],[Average TTFT]]/0.44) -> 0.39877273 | V12: 3000000000 | W12: https://www.technobezz.com/news/google-slashes-free-gemini-api-requests-to-20-per-day-2025-12-20-gl06 | X12: =2.25*(10^12) -> 2250000000000 | Y12: =1500*(1-EXP(-(Tableau1[[#This Row],[P_total]]^2)/1000))*Tableau1[[#This Row],[P_total]]*10^9 -> 3e+15 | Z12: 45637 | AA12: Epoch Ai | AB12: =IF(Tableau1[[#This Row],[Date de publication]]>=EDATE(TODAY(),-24),"Oui","Non") -> Oui | AC12: 9000000 | AD12: https://www.cnbc.com/2025/11/21/google-must-double-ai-serving-capacity-every-6-months-to-meet-demand.html
A13: Oui | B13: Mistral AI | C13: Codestral | D13: Moyen | E13: Dense | G13: 22.25 | H13: 22.25 | K13: ['https://docs.mistral.ai/getting-started/models/', 'https://mistral.ai/news/codestral'] | L13: SW | M13: 1.16 | N13: "Only available for Sweden (Norway data center excluded) https://datacenters.microsoft.com/sustainability/efficiency/" | O13: 0.09 | P13: "Only available for Sweden (Norway data center excluded) https://datacenters.microsoft.com/sustainability/efficiency/" | Q13: =IF( NOT(ISBLANK(F13)), F13, IF( AND(NOT(ISBLANK(G13)), NOT(ISBLANK(H13))), INT(AVERAGE(G13, H13)), "" ) ) -> 22 | R13: =IF( NOT(ISBLANK(I13)), INT(AVERAGE(I13,J13)), IF( AND(NOT(ISBLANK(G13)), NOT(ISBLANK(H13))), INT(AVERAGE(G13, H13)), "" ) ) -> 22 | S13: 54.4 | T13: 0.23 | U13: =0.062*(Tableau1[[#This Row],[Average TTFT]]/0.44) -> 0.032409091 | V13: 40000000 | W13: https://fueler.io/blog/mistral-ai-usage-revenue-valuation-growth-statistics | X13: =2.25*(10^12) -> 2250000000000 | Y13: =1500*(1-EXP(-(Tableau1[[#This Row],[P_total]]^2)/1000))*Tableau1[[#This Row],[P_total]]*10^9 -> 1.2661664e+13 | Z13: 45670 | AA13: Mistral AI | AB13: =IF(Tableau1[[#This Row],[Date de publication]]>=EDATE(TODAY(),-24),"Oui","Non") -> Oui | AC13: 200000 | AD13: https://www.cnbc.com/2026/03/30/mistral-ai-paris-data-center-cluster-debt-financing.html
A14: Oui | B14: Mistral AI | C14: Magistral Medium | D14: Moyen | E14: Dense | G14: 70 | H14: 120 | K14: ['https://docs.mistral.ai/getting-started/models/'] | L14: SW | M14: 1.16 | N14: "Only available for Sweden (Norway data center excluded) https://datacenters.microsoft.com/sustainability/efficiency/" | O14: 0.09 | P14: "Only available for Sweden (Norway data center excluded) https://datacenters.microsoft.com/sustainability/efficiency/" | Q14: =IF( NOT(ISBLANK(F14)), F14, IF( AND(NOT(ISBLANK(G14)), NOT(ISBLANK(H14))), INT(AVERAGE(G14, H14)), "" ) ) -> 95 | R14: =IF( NOT(ISBLANK(I14)), INT(AVERAGE(I14,J14)), IF( AND(NOT(ISBLANK(G14)), NOT(ISBLANK(H14))), INT(AVERAGE(G14, H14)), "" ) ) -> 95 | S14: 48.6 | T14: 0.41 | U14: =0.062*(Tableau1[[#This Row],[Average TTFT]]/0.44) -> 0.057772727 | V14: 40000000 | W14: https://fueler.io/blog/mistral-ai-usage-revenue-valuation-growth-statistics | X14: =2.25*(10^12) -> 2250000000000 | Y14: =1500*(1-EXP(-(Tableau1[[#This Row],[P_total]]^2)/1000))*Tableau1[[#This Row],[P_total]]*10^9 -> 1.4248285e+14 | Z14: 45818 | AA14: Mistral AI | AB14: =IF(Tableau1[[#This Row],[Date de publication]]>=EDATE(TODAY(),-24),"Oui","Non") -> Oui | AC14: 200000 | AD14: https://www.cnbc.com/2026/03/30/mistral-ai-paris-data-center-cluster-debt-financing.html
A15: Oui | B15: Mistral AI | C15: Ministral 3b | D15: Petit | E15: Dense | G15: 3.32 | H15: 3.32 | K15: ['https://docs.mistral.ai/getting-started/models/', 'https://mistral.ai/news/ministraux'] | L15: SW | M15: 1.16 | N15: "Only available for Sweden (Norway data center excluded) https://datacenters.microsoft.com/sustainability/efficiency/" | O15: 0.09 | P15: "Only available for Sweden (Norway data center excluded) https://datacenters.microsoft.com/sustainability/efficiency/" | Q15: =IF( NOT(ISBLANK(F15)), F15, IF( AND(NOT(ISBLANK(G15)), NOT(ISBLANK(H15))), INT(AVERAGE(G15, H15)), "" ) ) -> 3 | R15: =IF( NOT(ISBLANK(I15)), INT(AVERAGE(I15,J15)), IF( AND(NOT(ISBLANK(G15)), NOT(ISBLANK(H15))), INT(AVERAGE(G15, H15)), "" ) ) -> 3 | S15: 65.2 | T15: 0.23 | U15: =0.062*(Tableau1[[#This Row],[Average TTFT]]/0.44) -> 0.032409091 | V15: 40000000 | W15: https://fueler.io/blog/mistral-ai-usage-revenue-valuation-growth-statistics | X15: =2.25*(10^12) -> 2250000000000 | Y15: =1500*(1-EXP(-(Tableau1[[#This Row],[P_total]]^2)/1000))*Tableau1[[#This Row],[P_total]]*10^9 -> 4.0318296e+10 | Z15: 45574 | AA15: Mistral AI | AB15: =IF(Tableau1[[#This Row],[Date de publication]]>=EDATE(TODAY(),-24),"Oui","Non") -> Oui | AC15: 200000 | AD15: https://www.cnbc.com/2026/03/30/mistral-ai-paris-data-center-cluster-debt-financing.html
A16: Oui | B16: Mistral AI | C16: Ministral 8b | D16: Petit | E16: Dense | G16: 8.02 | H16: 8.02 | K16: ['https://docs.mistral.ai/getting-started/models/', 'https://mistral.ai/news/ministraux'] | L16: SW | M16: 1.16 | N16: "Only available for Sweden (Norway data center excluded) https://datacenters.microsoft.com/sustainability/efficiency/" | O16: 0.09 | P16: "Only available for Sweden (Norway data center excluded) https://datacenters.microsoft.com/sustainability/efficiency/" | Q16: =IF( NOT(ISBLANK(F16)), F16, IF( AND(NOT(ISBLANK(G16)), NOT(ISBLANK(H16))), INT(AVERAGE(G16, H16)), "" ) ) -> 8 | R16: =IF( NOT(ISBLANK(I16)), INT(AVERAGE(I16,J16)), IF( AND(NOT(ISBLANK(G16)), NOT(ISBLANK(H16))), INT(AVERAGE(G16, H16)), "" ) ) -> 8 | S16: 87.8 | T16: 0.27 | U16: =0.062*(Tableau1[[#This Row],[Average TTFT]]/0.44) -> 0.038045455 | V16: 40000000 | W16: https://fueler.io/blog/mistral-ai-usage-revenue-valuation-growth-statistics | X16: =2.25*(10^12) -> 2250000000000 | Y16: =1500*(1-EXP(-(Tableau1[[#This Row],[P_total]]^2)/1000))*Tableau1[[#This Row],[P_total]]*10^9 -> 7.4394001e+11 | Z16: 45574 | AA16: Mistral AI | AB16: =IF(Tableau1[[#This Row],[Date de publication]]>=EDATE(TODAY(),-24),"Oui","Non") -> Oui | AC16: 200000 | AD16: https://www.cnbc.com/2026/03/30/mistral-ai-paris-data-center-cluster-debt-financing.html
A17: Oui | B17: Mistral AI | C17: Mistral Large | D17: Grand | E17: Dense | G17: 122.61 | H17: 122.61 | K17: ['https://docs.mistral.ai/getting-started/models/', 'https://mistral.ai/news/mistral-large-2407'] | L17: SW | M17: 1.16 | N17: "Only available for Sweden (Norway data center excluded) https://datacenters.microsoft.com/sustainability/efficiency/" | O17: 0.09 | P17: "Only available for Sweden (Norway data center excluded) https://datacenters.microsoft.com/sustainability/efficiency/" | Q17: =IF( NOT(ISBLANK(F17)), F17, IF( AND(NOT(ISBLANK(G17)), NOT(ISBLANK(H17))), INT(AVERAGE(G17, H17)), "" ) ) -> 122 | R17: =IF( NOT(ISBLANK(I17)), INT(AVERAGE(I17,J17)), IF( AND(NOT(ISBLANK(G17)), NOT(ISBLANK(H17))), INT(AVERAGE(G17, H17)), "" ) ) -> 122 | S17: 35.6 | T17: 0.45 | U17: =0.062*(Tableau1[[#This Row],[Average TTFT]]/0.44) -> 0.063409091 | V17: 40000000 | W17: https://fueler.io/blog/mistral-ai-usage-revenue-valuation-growth-statistics | X17: =2.25*(10^12) -> 2250000000000 | Y17: =1500*(1-EXP(-(Tableau1[[#This Row],[P_total]]^2)/1000))*Tableau1[[#This Row],[P_total]]*10^9 -> 1.8299994e+14 | Z17: 45348 | AA17: Epoch Ai | AB17: =IF(Tableau1[[#This Row],[Date de publication]]>=EDATE(TODAY(),-24),"Oui","Non") -> Non | AC17: 200000 | AD17: https://www.cnbc.com/2026/03/30/mistral-ai-paris-data-center-cluster-debt-financing.html
A18: Oui | B18: Mistral AI | C18: Mistral Medium | D18: Moyen | E18: Dense | G18: 70 | H18: 120 | K18: ['https://docs.mistral.ai/getting-started/models/'] | L18: SW | M18: 1.16 | N18: "Only available for Sweden (Norway data center excluded) https://datacenters.microsoft.com/sustainability/efficiency/" | O18: 0.09 | P18: "Only available for Sweden (Norway data center excluded) https://datacenters.microsoft.com/sustainability/efficiency/" | Q18: =IF( NOT(ISBLANK(F18)), F18, IF( AND(NOT(ISBLANK(G18)), NOT(ISBLANK(H18))), INT(AVERAGE(G18, H18)), "" ) ) -> 95 | R18: =IF( NOT(ISBLANK(I18)), INT(AVERAGE(I18,J18)), IF( AND(NOT(ISBLANK(G18)), NOT(ISBLANK(H18))), INT(AVERAGE(G18, H18)), "" ) ) -> 95 | S18: 45.1 | T18: 0.59 | U18: =0.062*(Tableau1[[#This Row],[Average TTFT]]/0.44) -> 0.083136364 | V18: 40000000 | W18: https://fueler.io/blog/mistral-ai-usage-revenue-valuation-growth-statistics | X18: =2.25*(10^12) -> 2250000000000 | Y18: =1500*(1-EXP(-(Tableau1[[#This Row],[P_total]]^2)/1000))*Tableau1[[#This Row],[P_total]]*10^9 -> 1.4248285e+14 | Z18: 45881 | AA18: Mistral AI | AB18: =IF(Tableau1[[#This Row],[Date de publication]]>=EDATE(TODAY(),-24),"Oui","Non") -> Oui | AC18: 200000 | AD18: https://www.cnbc.com/2026/03/30/mistral-ai-paris-data-center-cluster-debt-financing.html
A19: Oui | B19: Mistral AI | C19: Pixtral Large | D19: Grand | E19: Dense | G19: 123 | H19: 123 | K19: ['https://docs.mistral.ai/getting-started/models/', 'https://mistral.ai/news/pixtral-large'] | L19: SW | M19: 1.16 | N19: "Only available for Sweden (Norway data center excluded) https://datacenters.microsoft.com/sustainability/efficiency/" | O19: 0.09 | P19: "Only available for Sweden (Norway data center excluded) https://datacenters.microsoft.com/sustainability/efficiency/" | Q19: =IF( NOT(ISBLANK(F19)), F19, IF( AND(NOT(ISBLANK(G19)), NOT(ISBLANK(H19))), INT(AVERAGE(G19, H19)), "" ) ) -> 123 | R19: =IF( NOT(ISBLANK(I19)), INT(AVERAGE(I19,J19)), IF( AND(NOT(ISBLANK(G19)), NOT(ISBLANK(H19))), INT(AVERAGE(G19, H19)), "" ) ) -> 123 | S19: 35.6 | T19: 0.45 | U19: =0.062*(Tableau1[[#This Row],[Average TTFT]]/0.44) -> 0.063409091 | V19: 40000000 | W19: https://fueler.io/blog/mistral-ai-usage-revenue-valuation-growth-statistics | X19: =2.25*(10^12) -> 2250000000000 | Y19: =1500*(1-EXP(-(Tableau1[[#This Row],[P_total]]^2)/1000))*Tableau1[[#This Row],[P_total]]*10^9 -> 1.8449995e+14 | Z19: 45614 | AA19: Epoch Ai | AB19: =IF(Tableau1[[#This Row],[Date de publication]]>=EDATE(TODAY(),-24),"Oui","Non") -> Oui | AC19: 200000 | AD19: https://www.cnbc.com/2026/03/30/mistral-ai-paris-data-center-cluster-debt-financing.html
